Workbook

Sheet People
A1: Id | B1: Name | C1: DisplayName | D1: Dob | E1: GenderId | F1: IsFamilyHead | G1: FamilyHead
A2: 1 | B2: Arun Venkatesan | C2: Arun | D2: 31092 | E2: 1 | F2: TRUE
A3: 2 | B3: Kurinji Malar Paranthaman | C3: Kurinji | D3: 33526 | E3: 2 | G3: Arun Venkatesan
A4: 3 | B4: Aarna Arun | C4: Aarna | D4: 42978 | E4: 2 | G4: Arun Venkatesan
A5: 4 | B5: Aadhav Arun | C5: Aadhav | D5: 44127 | E5: 1 | G5: Arun Venkatesan

Sheet Equity
A1: ISIN | B1: Company | C1: NSE Symbol | D1: BSE Code | E1: Incorporation Date | F1: ISIN Creation Date
A2: INE238A01034 | B2: Axis Bank Ltd | C2: AXISBANK | D2: 532215 | E2: 03-Dec-1993
A3: INE457A01014 | B3: Bank of Maharashtra | C3: MAHABANK | D3: 532525 | E3: 16-Sep-1935
A4: INE323A01026 | B4: Bosch Ltd | C4: BOSCHLTD | D4: 500530 | E4: 12-Nov-1951
A5: INE925R01014 | B5: CMS Info Systems Ltd | C5: CMSINFO | D5: 543441 | E5: 26-Mar-2008
A6: INE335K01011 | B6: Coffee Day Enterprises Ltd | C6: COFFEEDAY | D6: 539436 | E6: 20-Jun-2008
A7: INE0KL801015 | B7: DCX System Ltd | C7: DCXINDIA | D7: 543650 | E7: 16-Dec-2011 | F7: 44876
A8: INE129A01019 | B8: GAIL (INDIA) Ltd | C8: GAIL | D8: 532155 | E8: 16-Aug-1984
A9: INE040A01034 | B9: HDFC Bank Ltd | C9: HDFCBANK | D9: 500180 | E9: 30-Aug-1994 | F9: 34845
A10: INE090A01021 | B10: ICICI Bank Ltd | C10: ICICIBANK | D10: 532174 | E10: 05-Jan-1994
A11: INE092T01019 | B11: IDFC First Bank Ltd | C11: IDFCFIRSTB | D11: 539437 | E11: 21-Oct-2014
A12: INE562A01011 | B12: Indian Bank | C12: INDIANB | D12: 532814 | E12: 05-Mar-1907 | F12: 43752
A13: INE053A01029 | B13: Indian Hotels Company Ltd | C13: INDHOTEL | D13: 500850 | E13: 01-Apr-1902 | F13: 44497
A14: INE009A01021 | B14: Infosys Ltd | C14: INFY | D14: 500209 | E14: 02-Jul-1981 | F14: 45686
A15: INE335Y01012 | B15: IRCTC Ltd | C15: IRCTC | D15: 542830 | E15: 27-Sep-1999
A16: INE335Y01020 | B16: IRCTC Ltd | C16: IRCTC | D16: 542830 | E16: 27-Sep-1999
A17: INE379A01028 | B17: ITC Hotels Ltd | C17: ITCHOTELS | D17: 544325 | E17: 28-Jul-2023
A18: INE154A01025 | B18: ITC Ltd | C18: ITC | D18: 500875 | E18: 24-Aug-1910
A19: INE351F01018 | B19: Jaiprakash Power Ventures Ltd | C19: JPPOWER | D19: 532627 | E19: 21-Dec-1994
A20: INE498L01015 | B20: L&T Finance Ltd | C20: L&TFH | D20: 533519 | E20: 01-May-2008
A21: INE018A01030 | B21: Larsen & Tubro Ltd | C21: LT | D21: 500510 | E21: 07-Feb-1946
A22: INE848E01016 | B22: NHPC Ltd | C22: NHPC | D22: 533098 | E22: 07-Nov-1975
A23: INE0LXG01040 | B23: OLA Electric Mobility Ltd | C23: OLA | D23: 544225 | E23: 03-Feb-2017 | F23: 45513
A24: INE1NPP01017 | B24: Siemens Energy India Ltd | C24: ENRIN | D24: 544390 | E24: 07-Feb-2024 | F24: 45827
A25: INE003A01024 | B25: Siemens Ltd | C25: SIEMENS | D25: 505372 | E25: 02-Mar-1957
A26: INE114A01011 | B26: Steel Authority of India Ltd (SAIL) | C26: SAIL | D26: 500113 | E26: 24-Jan-1973
A27: INE040H01021 | B27: Suzlon Engergy Ltd | C27: SUZLON | D27: 532667 | E27: 10-Apr-1995 | F27: 45303
A28: INE155A01022 | B28: Tata Motors Ltd | C28: TATAMOTORS | D28: 500570 | E28: 01-Sep-1945
A29: INE1TAE01010 | B29: Tata Motors Passenger Vehicles Ltd (TMPV) | C29: TMPV | D29: 500570 | E29: 01-Sep-1945 | F29: 45839
A30: INE081A01012 | B30: Tata Steel Ltd | C30: TATASTEEL | D30: 500470 | E30: 26-Aug-1907
A31: INE081A01020 | B31: Tata Steel Ltd | C31: TATASTEEL | D31: 500470 | E31: 26-Aug-1907 | F31: 44770

Sheet Equity Transaction
A1: Person | B1: Account | C1: Trade Date | D1: ISIN | E1: Security | F1: Segment | G1: Action | H1: Quantity | I1: Price/Share | J1: Net Amount | K1: BrokeragePerUnit | L1: NetBrokerage | M1: STT | N1: Stamp Duty | O1: GST | P1: Total Amount
A2: Arun Venkatesan | B2: ICICI | C2: 43949 | D2: INE090A01021 | E2: ICICI BANK LTD. | F2: CASH | G2: Buy | H2: 20 | I2: 353.75 | J2: =H2*I2 -> 7075 | K2: 1.25 | L2: =Table1[[#This Row],[Quantity]]*Table1[[#This Row],[BrokeragePerUnit]] -> 25 | M2: 7 | N2: 0.45 | O2: 4.52 | P2: =Table1[[#This Row],[Net Amount]]+Table1[[#This Row],[NetBrokerage]]+Table1[[#This Row],[STT]]+Table1[[#This Row],[Stamp Duty]]+Table1[[#This Row],[GST]] -> 7111.97
A3: Arun Venkatesan | B3: ICICI | C3: 44018 | D3: INE040A01034 | E3: HDFC BANK LTD | F3: CASH | G3: Buy | H3: 10 | I3: 1100 | J3: =H3*I3 -> 11000 | K3: 6.05 | L3: =Table1[[#This Row],[Quantity]]*Table1[[#This Row],[BrokeragePerUnit]] -> 60.5 | M3: 11 | N3: 2 | O3: 10.95 | P3: =Table1[[#This Row],[Net Amount]]+Table1[[#This Row],[NetBrokerage]]+Table1[[#This Row],[STT]]+Table1[[#This Row],[Stamp Duty]]+Table1[[#This Row],[GST]] -> 11084.45
A4: Arun Venkatesan | B4: ICICI | C4: 44550 | D4: INE562A01011 | E4: INDIAN BANK | F4: CASH | G4: Buy | H4: 62 | I4: 136.45 | J4: =H4*I4 -> 8459.9 | K4: 0.75 | L4: =Table1[[#This Row],[Quantity]]*Table1[[#This Row],[BrokeragePerUnit]] -> 46.5 | M4: 0 | N4: 0 | O4: 0 | P4: =Table1[[#This Row],[Net Amount]]+Table1[[#This Row],[NetBrokerage]]+Table1[[#This Row],[STT]]+Table1[[#This Row],[Stamp Duty]]+Table1[[#This Row],[GST]] -> 8506.4
A5: Arun Venkatesan | B5: ICICI | C5: 44550 | D5: INE562A01011 | E5: INDIAN BANK | F5: CASH | G5: Buy | H5: 38 | I5: 136.45 | J5: =H5*I5 -> 5185.1 | K5: 0.75 | L5: =Table1[[#This Row],[Quantity]]*Table1[[#This Row],[BrokeragePerUnit]] -> 28.5 | M5: 13.99 | N5: 2 | O5: 13.55 | P5: =Table1[[#This Row],[Net Amount]]+Table1[[#This Row],[NetBrokerage]]+Table1[[#This Row],[STT]]+Table1[[#This Row],[Stamp Duty]]+Table1[[#This Row],[GST]] -> 5243.14
A6: Arun Venkatesan | B6: ICICI | C6: 44553 | D6: INE040A01034 | E6: HDFC BANK LTD | F6: CASH | G6: Buy | H6: 10 | I6: 1450 | J6: =H6*I6 -> 14500 | K6: 7.97 | L6: =Table1[[#This Row],[Quantity]]*Table1[[#This Row],[BrokeragePerUnit]] -> 79.7 | M6: 14.4 | N6: 2.18 | O6: 14.4 | P6: =Table1[[#This Row],[Net Amount]]+Table1[[#This Row],[NetBrokerage]]+Table1[[#This Row],[STT]]+Table1[[#This Row],[Stamp Duty]]+Table1[[#This Row],[GST]] -> 14610.68
A7: Arun Venkatesan | B7: ICICI | C7: 44553 | D7: INE090A01021 | E7: ICICI BANK LTD. | F7: CASH | G7: Buy | H7: 20 | I7: 730 | J7: =H7*I7 -> 14600 | K7: 4.015 | L7: =Table1[[#This Row],[Quantity]]*Table1[[#This Row],[BrokeragePerUnit]] -> 80.3 | M7: 14.6 | N7: 1.82 | O7: 14.5 | P7: =Table1[[#This Row],[Net Amount]]+Table1[[#This Row],[NetBrokerage]]+Table1[[#This Row],[STT]]+Table1[[#This Row],[Stamp Duty]]+Table1[[#This Row],[GST]] -> 14711.22
A8: Arun Venkatesan | B8: ICICI | C8: 44559 | D8: INE925R01014 | E8: CMS INFO SYSTEMS LIMITED | F8: CASH | G8: IPO | H8: 69 | I8: 216 | J8: =H8*I8 -> 14904 | L8: =H8*K8 -> 0 | P8: =J8+L8 -> 14904
A9: Arun Venkatesan | B9: ICICI | C9: 44880 | D9: INE040A01034 | E9: HDFC BANK LTD | F9: CASH | G9: Buy | H9: 20 | I9: 1608.7 | J9: =H9*I9 -> 32174 | K9: 3.5 | L9: =Table1[[#This Row],[Quantity]]*Table1[[#This Row],[BrokeragePerUnit]] -> 70 | M9: 32.17 | N9: 5.28 | O9: 12.93 | P9: =Table1[[#This Row],[Net Amount]]+Table1[[#This Row],[NetBrokerage]]+Table1[[#This Row],[STT]]+Table1[[#This Row],[Stamp Duty]]+Table1[[#This Row],[GST]] -> 32294.38
A10: Arun Venkatesan | B10: ICICI | C10: 44880 | D10: INE090A01021 | E10: ICICI BANK LTD. | F10: CASH | G10: Buy | H10: 20 | I10: 906.5 | J10: =H10*I10 -> 18130 | K10: 1.99 | L10: =Table1[[#This Row],[Quantity]]*Table1[[#This Row],[BrokeragePerUnit]] -> 39.8 | M10: 17.82 | N10: 2.72 | O10: 7.28 | P10: =Table1[[#This Row],[Net Amount]]+Table1[[#This Row],[NetBrokerage]]+Table1[[#This Row],[STT]]+Table1[[#This Row],[Stamp Duty]]+Table1[[#This Row],[GST]] -> 18197.62
A11: Arun Venkatesan | B11: ICICI | C11: 44880 | D11: INE848E01016 | E11: NHPC LTD | F11: CASH | G11: Buy | H11: 1 | I11: 43.8 | J11: =H11*I11 -> 43.8 | K11: 0.02 | L11: =Table1[[#This Row],[Quantity]]*Table1[[#This Row],[BrokeragePerUnit]] -> 0.02 | P11: =Table1[[#This Row],[Net Amount]]+Table1[[#This Row],[NetBrokerage]]+Table1[[#This Row],[STT]]+Table1[[#This Row],[Stamp Duty]]+Table1[[#This Row],[GST]] -> 43.82
A12: Arun Venkatesan | B12: ICICI | C12: 44880 | D12: INE848E01016 | E12: NHPC LTD | F12: CASH | G12: Sell | H12: 1 | I12: 43.75 | J12: =H12*I12 -> 43.75 | K12: 0.02 | L12: =Table1[[#This Row],[Quantity]]*Table1[[#This Row],[BrokeragePerUnit]] -> 0.02 | P12: =Table1[[#This Row],[Net Amount]]+Table1[[#This Row],[NetBrokerage]]+Table1[[#This Row],[STT]]+Table1[[#This Row],[Stamp Duty]]+Table1[[#This Row],[GST]] -> 43.77
A13: Arun Venkatesan | B13: ICICI | C13: 44882 | D13: INE090A01021 | E13: ICICI BANK LTD. | F13: CASH | G13: Buy | H13: 20 | I13: 918 | J13: =H13*I13 -> 18360 | K13: 2.01 | L13: =Table1[[#This Row],[Quantity]]*Table1[[#This Row],[BrokeragePerUnit]] -> 40.2 | M13: 18 | N13: 3 | O13: 7.36 | P13: =Table1[[#This Row],[Net Amount]]+Table1[[#This Row],[NetBrokerage]]+Table1[[#This Row],[STT]]+Table1[[#This Row],[Stamp Duty]]+Table1[[#This Row],[GST]] -> 18428.56
A14: Arun Venkatesan | B14: ICICI | C14: 44994 | D14: INE040A01034 | E14: HDFC BANK LTD | F14: CASH | G14: Buy | H14: 30 | I14: 1635 | J14: =H14*I14 -> 49050 | K14: 3.59 | L14: =Table1[[#This Row],[Quantity]]*Table1[[#This Row],[BrokeragePerUnit]] -> 107.7 | M14: 49 | N14: 7 | O14: 19.72 | P14: =Table1[[#This Row],[Net Amount]]+Table1[[#This Row],[NetBrokerage]]+Table1[[#This Row],[STT]]+Table1[[#This Row],[Stamp Duty]]+Table1[[#This Row],[GST]] -> 49233.42
A15: Arun Venkatesan | B15: ICICI | C15: 45021 | D15: INE090A01021 | E15: ICICI BANK LTD. | F15: CASH | G15: Buy | H15: 20 | I15: 880 | J15: =H15*I15 -> 17600 | K15: 1.93 | L15: =Table1[[#This Row],[Quantity]]*Table1[[#This Row],[BrokeragePerUnit]] -> 38.6 | M15: 17.6 | N15: 2.64 | O15: 7.06 | P15: =Table1[[#This Row],[Net Amount]]+Table1[[#This Row],[NetBrokerage]]+Table1[[#This Row],[STT]]+Table1[[#This Row],[Stamp Duty]]+Table1[[#This Row],[GST]] -> 17665.9
A16: Arun Venkatesan | B16: ICICI | C16: 45021 | D16: INE562A01011 | E16: INDIAN BANK | F16: CASH | G16: Buy | H16: 100 | I16: 289.55 | J16: =H16*I16 -> 28955 | K16: 0.63 | L16: =Table1[[#This Row],[Quantity]]*Table1[[#This Row],[BrokeragePerUnit]] -> 63 | M16: 29.39 | N16: 4.36 | O16: 11.61 | P16: =Table1[[#This Row],[Net Amount]]+Table1[[#This Row],[NetBrokerage]]+Table1[[#This Row],[STT]]+Table1[[#This Row],[Stamp Duty]]+Table1[[#This Row],[GST]] -> 29063.36
A17: Arun Venkatesan | B17: ICICI | C17: 45026 | D17: INE040A01034 | E17: HDFC BANK LTD | F17: CASH | G17: Buy | H17: 30 | I17: 1663 | J17: =H17*I17 -> 49890 | K17: 3.65 | L17: =Table1[[#This Row],[Quantity]]*Table1[[#This Row],[BrokeragePerUnit]] -> 109.5 | M17: 50 | N17: 7 | O17: 20.01 | P17: =Table1[[#This Row],[Net Amount]]+Table1[[#This Row],[NetBrokerage]]+Table1[[#This Row],[STT]]+Table1[[#This Row],[Stamp Duty]]+Table1[[#This Row],[GST]] -> 50076.51
A18: Arun Venkatesan | B18: ICICI | C18: 45758 | D18: INE549K07824 | E18: NCD | G18: Sell | H18: 20 | I18: 984 | J18: =H18*I18 -> 19680 | L18: =Table1[[#This Row],[Quantity]]*Table1[[#This Row],[BrokeragePerUnit]] -> 0 | P18: =Table1[[#This Row],[Net Amount]]+Table1[[#This Row],[NetBrokerage]]+Table1[[#This Row],[STT]]+Table1[[#This Row],[Stamp Duty]]+Table1[[#This Row],[GST]] -> 19680
A19: Arun Venkatesan | B19: ICICI | C19: 45758 | D19: INE549K07824 | E19: NCD | G19: Sell | H19: 180 | I19: 984 | J19: =H19*I19 -> 177120 | L19: =Table1[[#This Row],[Quantity]]*Table1[[#This Row],[BrokeragePerUnit]] -> 0 | P19: =Table1[[#This Row],[Net Amount]]+Table1[[#This Row],[NetBrokerage]]+Table1[[#This Row],[STT]]+Table1[[#This Row],[Stamp Duty]]+Table1[[#This Row],[GST]] -> 177120
A20: Arun Venkatesan | B20: ICICI | C20: 45895 | D20: INE040A01034 | E20: HDFC BANK LTD | F20: DIVIDEND | G20: Bonus | H20: 100 | J20: =H20*I20 -> 0 | L20: =H20*K20 -> 0 | P20: =J20+L20 -> 0
A21: Arun Venkatesan | B21: IIFL | C21: 41624 | D21: INE081A01012 | E21: Tata Steel | F21: CASH | G21: BUY | H21: 4 | I21: 410.64 | J21: =H21*I21 -> 1642.56 | P21: 1642.56
A22: Arun Venkatesan | B22: IIFL | C22: 41940 | D22: INE018A01030 | E22: L & T LTD | F22: CASH | G22: BUY | H22: 2 | I22: 1581.45 | J22: =H22*I22 -> 3162.9 | K22: 12.5 | L22: =H22*K22 -> 25 | P22: =J22+L22 -> 3187.9
A23: Arun Venkatesan | B23: IIFL | C23: 41940 | D23: INE498L01015 | E23: L&T FINANCE LTD | F23: CASH | G23: BUY | H23: 50 | I23: 68.7 | J23: =H23*I23 -> 3435 | K23: 0.5 | L23: =H23*K23 -> 25 | P23: =J23+L23 -> 3460
A24: Arun Venkatesan | B24: IIFL | C24: 41940 | D24: INE081A01012 | E24: Tata Steel | F24: CASH | G24: BUY | H24: 10 | I24: 452.7 | J24: =H24*I24 -> 4527 | K24: 2.5 | L24: =H24*K24 -> 25 | P24: =J24+L24 -> 4552
A25: Arun Venkatesan | B25: IIFL | C25: 41942 | D25: INE498L01015 | E25: L&T FINANCE LTD | F25: CASH | G25: BUY | H25: 50 | I25: 68 | J25: =H25*I25 -> 3400 | K25: 0.5 | L25: =H25*K25 -> 25 | P25: =J25+L25 -> 3425
A26: Arun Venkatesan | B26: IIFL | C26: 41960 | D26: INE018A01030 | E26: L & T LTD | F26: CASH | G26: BUY | H26: 2 | I26: 1613.3 | J26: =H26*I26 -> 3226.6 | K26: 12.5 | L26: =H26*K26 -> 25 | P26: =J26+L26 -> 3251.6
A27: Arun Venkatesan | B27: IIFL | C27: 42059 | D27: INE081A01012 | E27: Tata Steel | F27: CASH | G27: BUY | H27: 20 | I27: 360 | J27: =H27*I27 -> 7200 | K27: 1.8 | L27: =H27*K27 -> 36 | P27: =J27+L27 -> 7236
A28: Arun Venkatesan | B28: IIFL | C28: 42065 | D28: INE081A01012 | E28: Tata Steel | F28: CASH | G28: BUY | H28: 20 | I28: 350 | J28: =H28*I28 -> 7000 | K28: 1.75 | L28: =H28*K28 -> 35 | P28: =J28+L28 -> 7035
A29: Arun Venkatesan | B29: IIFL | C29: 42156 | D29: INE018A01030 | E29: L & T LTD | F29: CASH | G29: BUY | H29: 3 | I29: 1700 | J29: =H29*I29 -> 5100 | K29: 8.5 | L29: =H29*K29 -> 25.5 | P29: =J29+L29 -> 5125.5
A30: Arun Venkatesan | B30: IIFL | C30: 42156 | D30: INE018A01030 | E30: L & T LTD | F30: CASH | G30: BUY | H30: 2 | I30: 1700 | J30: =H30*I30 -> 3400 | K30: 8.5 | L30: =H30*K30 -> 17 | P30: =J30+L30 -> 3417
A31: Arun Venkatesan | B31: IIFL | C31: 42167 | D31: INE081A01012 | E31: Tata Steel | F31: CASH | G31: BUY | H31: 30 | I31: 298 | J31: =H31*I31 -> 8940 | K31: 1.49 | L31: =H31*K31 -> 44.7 | P31: =J31+L31 -> 8984.7
A32: Arun Venkatesan | B32: IIFL | C32: 42170 | D32: INE009A01021 | E32: INFY | F32: CASH | G32: BUY | H32: 3 | I32: 992 | J32: =H32*I32 -> 2976 | K32: 4.96 | L32: =H32*K32 -> 14.88 | P32: =J32+L32 -> 2990.88
A33: Arun Venkatesan | B33: IIFL | C33: 42170 | D33: INE009A01021 | E33: INFY | F33: CASH | G33: BUY | H33: 10 | I33: 992 | J33: =H33*I33 -> 9920 | K33: 4.96 | L33: =H33*K33 -> 49.6 | P33: =J33+L33 -> 9969.6
... A42: Arun Venkatesan | B42: IIFL | C42: 42234 | D42: INE081A01012 | E42: Tata Steel | F42: CASH | G42: BUY | H42: 1 | I42: 249 | J42: =H42*I42 -> 249 | K42: 1.56 | L42: =H42*K42 -> 1.56 | P42: =J42+L42 -> 250.56
A43: Arun Venkatesan | B43: IIFL | C43: 42933 | D43: INE018A01030 | E43: L & T LTD | F43: DIVIDEND | G43: Bonus | H43: 4 | J43: =H43*I43 -> 0 | L43: =H43*K43 -> 0 | P43: =J43+L43 -> 0
A44: Arun Venkatesan | B44: IIFL | C44: 43350 | D44: INE009A01021 | E44: INFY | F44: DIVIDEND | G44: Bonus | H44: 53 | J44: =H44*I44 -> 0 | L44: =H44*K44 -> 0 | P44: =J44+L44 -> 0
A45: Arun Venkatesan | B45: IIFL | C45: 43916 | D45: INE003A01024 | E45: SIEMENS | F45: CASH | G45: BUY | H45: 50 | I45: 1085 | J45: =H45*I45 -> 54250 | K45: 5.43 | L45: =H45*K45 -> 271.5 | P45: =J45+L45 -> 54521.5
A46: Arun Venkatesan | B46: IIFL | C46: 43917 | D46: INE323A01026 | E46: BOSCHLTD | F46: CASH | G46: Buy | H46: 6 | I46: 10000 | J46: =H46*I46 -> 60000 | K46: 50 | L46: =H46*K46 -> 300 | P46: =J46+L46 -> 60300
A47: Arun Venkatesan | B47: IIFL | C47: 43917 | D47: INE498L01015 | E47: L&T FINANCE LTD | F47: CASH | G47: Buy | H47: 50 | I47: 55 | J47: =H47*I47 -> 2750 | K47: 0.5 | L47: =H47*K47 -> 25 | P47: =J47+L47 -> 2775
A48: Arun Venkatesan | B48: IIFL | C48: 43917 | D48: INE018A01030 | E48: L & T LTD | F48: CASH | G48: Buy | H48: 30 | I48: 880 | J48: =H48*I48 -> 26400 | K48: 4.4 | L48: =H48*K48 -> 132 | P48: =J48+L48 -> 26532
...

Sheet Equity Dividend
A1: People | B1: Record Date | C1: Date | D1: Account | E1: ISIN | F1: Stock | G1: Nature | H1: Quantity | I1: Per Share | J1: Ratio | K1: Dividend Amount | L1: Total Units | M1: TaxOnDividend | N1: FinalAmount
A2: Arun Venkatesan | C2: 41870 | D2: IIFL | E2: INE081A01012 | F2: Tata Steel | H2: 100 | I2: 0.4 | K2: 40
A3: Arun Venkatesan | C3: 42230 | D3: IIFL | E3: INE081A01012 | F3: Tata Steel | H3: 100 | I3: 6.72 | K3: 672
A4: Arun Venkatesan | C4: 42258 | D4: IIFL | E4: INE018A01030 | F4: Larsen & Tubro | H4: 9 | I4: 16.25 | K4: 146.25
A5: Arun Venkatesan | C5: 42261 | D5: IIFL | E5: INE498L01015 | F5: L&T Finance | H5: 100 | I5: 0.8 | K5: 80
A6: Arun Venkatesan | C6: 42292 | D6: IIFL | E6: INE114A01011 | F6: Steel Authority of India | H6: 50 | K6: 12.5
A7: Arun Venkatesan | C7: 42298 | D7: IIFL | E7: INE009A01021 | F7: Infosys | H7: 53 | I7: 10 | K7: 530
A8: Arun Venkatesan | C8: 42541 | D8: IIFL | E8: INE009A01021 | F8: Infosys | H8: 53 | I8: 14.25 | K8: 755.25
A9: Arun Venkatesan | C9: 42598 | D9: IIFL | E9: INE081A01012 | F9: Tata Steel | H9: 100 | I9: 8 | K9: 800
A10: Arun Venkatesan | C10: 42612 | D10: IIFL | E10: INE018A01030 | F10: Larsen & Tubro | H10: 9 | I10: 18.25 | K10: 164.25
A11: Arun Venkatesan | C11: 42669 | D11: IIFL | E11: INE009A01021 | F11: Infosys | H11: 53 | I11: 11 | K11: 583
A12: Arun Venkatesan | C12: 42913 | D12: IIFL | E12: INE009A01021 | F12: Infosys | H12: 53 | I12: 14.75 | K12: 781.75
A13: Arun Venkatesan | C13: 42933 | D13: IIFL | E13: INE018A01030 | F13: Larsen & Tubro | H13: 0.5 | K13: 581.5
A14: Arun Venkatesan | C14: 42933 | D14: IIFL | E14: INE018A01030 | F14: Larsen & Tubro | G14: Bonus | H14: 4 | L14: 4
A15: Arun Venkatesan | C15: 42957 | D15: IIFL | E15: INE081A01012 | F15: Tata Steel | H15: 100 | I15: 10 | K15: 1000
A16: Arun Venkatesan | C16: 42971 | D16: IIFL | E16: INE018A01030 | F16: Larsen & Tubro | H16: 13 | I16: 14 | K16: 182
A17: Arun Venkatesan | C17: 42992 | D17: IIFL | E17: INE498L01015 | F17: L&T Finance | H17: 100 | I17: 0.8 | K17: 80
A18: Arun Venkatesan | C18: 43043 | D18: IIFL | E18: INE009A01021 | F18: Infosys | H18: 53 | I18: 13 | K18: 689
A19: Arun Venkatesan | C19: 43277 | D19: IIFL | E19: INE009A01021 | F19: Infosys | H19: 53 | I19: 30.5 | K19: 1616.5
A20: Arun Venkatesan | C20: 43304 | D20: IIFL | E20: INE081A01012 | F20: Tata Steel | H20: 100 | I20: 10 | K20: 1000
A21: Arun Venkatesan | C21: 43339 | D21: IIFL | E21: INE018A01030 | F21: Larsen & Tubro | H21: 13 | I21: 16 | K21: 208
A22: Arun Venkatesan | C22: 43343 | D22: IIFL | E22: INE498L01015 | F22: L&T Finance | H22: 100 | I22: 1 | K22: 100
A23: Arun Venkatesan | C23: 43360 | D23: IIFL | E23: INE009A01021 | F23: Infosys | G23: Bonus | H23: 53 | J23: 1:1 | L23: 53
A24: Arun Venkatesan | C24: 43403 | D24: IIFL | E24: INE009A01021 | F24: Infosys | H24: 106 | I24: 7 | K24: 742
A25: Arun Venkatesan | C25: 43493 | D25: IIFL | E25: INE009A01021 | F25: Infosys | H25: 106 | I25: 4 | K25: 424
A26: Arun Venkatesan | C26: 43641 | D26: IIFL | E26: INE009A01021 | F26: Infosys | H26: 106 | I26: 10.5 | K26: 1113
A27: Arun Venkatesan | C27: 43669 | D27: IIFL | E27: INE081A01012 | F27: Tata Steel | H27: 100 | I27: 13 | K27: 1300
A28: Arun Venkatesan | C28: 43678 | D28: IIFL | E28: INE498L01015 | F28: L&T Finance | H28: 100 | I28: 1 | K28: 100
A29: Arun Venkatesan | C29: 43682 | D29: IIFL | E29: INE018A01030 | F29: Larsen & Tubro | H29: 13 | I29: 18 | K29: 234
A30: Arun Venkatesan | C30: 43728 | D30: IIFL | E30: INE114A01011 | F30: Steel Authority of India | H30: 100 | I30: 0.5 | K30: 50
A31: Arun Venkatesan | C31: 43768 | D31: IIFL | E31: INE009A01021 | F31: Infosys | H31: 106 | I31: 8 | K31: 848
A32: Arun Venkatesan | C32: 43920 | D32: IIFL | E32: INE018A01030 | F32: Larsen & Tubro | H32: 13 | I32: 10 | K32: 130
A33: Arun Venkatesan | C33: 44015 | D33: IIFL | E33: INE009A01021 | F33: Infosys | H33: 106 | I33: 9.5 | K33: 1007
A34: Arun Venkatesan | C34: 44060 | D34: IIFL | E34: INE018A01030 | F34: Larsen & Tubro | H34: 43 | I34: 8 | K34: 344
A35: Arun Venkatesan | C35: 44067 | D35: IIFL | E35: INE081A01012 | F35: Tata Steel | H35: 100 | I35: 10 | K35: 1000
A36: Arun Venkatesan | C36: 44078 | D36: IIFL | E36: INE323A01026 | F36: Bosch Limited | H36: 6 | I36: 105 | K36: 630
A37: Kurinji Malar Paranthaman | C37: 44078 | D37: GEOGIT | E37: INE323A01026 | F37: Bosch Limited | H37: 2 | I37: 105 | K37: 210 | M37: 0 | N37: 0
A38: Arun Venkatesan | C38: 44145 | D38: IIFL | E38: INE018A01030 | F38: Larsen & Tubro | H38: 43 | I38: 18 | K38: 774
A39: Arun Venkatesan | C39: 44148 | D39: IIFL | E39: INE009A01021 | F39: Infosys | H39: 106 | I39: 12 | K39: 1272
A40: Arun Venkatesan | C40: 44243 | D40: IIFL | E40: INE003A01024 | F40: Siemens | H40: 50 | I40: 7 | K40: 350
...

Sheet Mutual Fund

Sheet Mutual Fund Transaction
A1: Person | B1: Account | C1: Date | D1: Transaction ID | E1: Transaction Type | F1: Fund Name | G1: Scheme Name | H1: Folio No | I1: Last recorded NAV | J1: Last recorded NAV On | K1: Div-Reinvestment | L1: Amount | M1: Secure Mind Premium Amount | N1: Unit | O1: Status | P1: Tax Saving | Q1: Channel
A2: Arun Venkatesan | B2: ICICI | C2: 43771 | D2: 82572277 | E2: Purchase | F2: ADITYA BIRLA SUN LIFE ASSET MANAGEMENT COMPANY LTD | G2: ADITYA BIRLA SUN LIFE ELSS TAX SAVER FUND - IDCW | H2: 1039297412 | I2: 152.47 | J2: 43773 | K2: N | L2: 4500 | M2: 0 | N2: 29.514 | O2: Executed | P2: Tax Receipt | Q2: Web
A3: Arun Venkatesan | B3: ICICI | C3: 43916 | D3: 87979374 | E3: Purchase | F3: HDFC ASSET MANAGEMENT COMPANY LIMITED | G3: HDFC Balanced Advantage Fund - Regular Plan - IDCW | H3: 16747427/33 | I3: 18.707 | J3: 43917 | K3: Y | L3: 5000 | M3: 0 | N3: 267.28 | O3: Executed | Q3: Web
A4: Arun Venkatesan | B4: ICICI | C4: 43917 | D4: 87993474 | E4: Purchase | F4: ICICI PRUDENTIAL MUTUAL FUND | G4: ICICI Prudential Midcap Fund - Growth | H4: 15070068/41 | I4: 64.34 | J4: 43917 | K4: N | L4: 5000 | M4: 0 | N4: 77.712 | O4: Executed | Q4: Web
A5: Arun Venkatesan | B5: ICICI | C5: 43949 | D5: 89034197 | E5: Div-Reinvestment | F5: HDFC ASSET MANAGEMENT COMPANY LIMITED | G5: HDFC Balanced Advantage Fund - Regular Plan - IDCW | H5: 16747427/33 | I5: 19.803 | J5: 43949 | K5: Y | L5: 55.47 | M5: 0 | N5: 2.801 | O5: Executed | Q5: SYS
A6: Arun Venkatesan | B6: ICICI | C6: 43949 | D6: 89024044 | E6: Purchase | F6: ICICI PRUDENTIAL MUTUAL FUND | G6: ICICI Prudential Midcap Fund - Growth | H6: 15070068/41 | I6: 69.75 | J6: 43949 | K6: N | L6: 20000 | M6: 0 | N6: 286.738 | O6: Executed | Q6: Web
A7: Arun Venkatesan | B7: ICICI | C7: 43949 | D7: 89024065 | E7: Purchase | F7: HDFC ASSET MANAGEMENT COMPANY LIMITED | G7: HDFC Balanced Advantage Fund - Regular Plan - IDCW | H7: 16747427/33 | I7: 19.82 | J7: 43949 | K7: Y | L7: 20000 | M7: 0 | N7: 1009.082 | O7: Executed | Q7: Web
A8: Arun Venkatesan | B8: ICICI | C8: 43952 | D8: 89163576 | E8: Purchase | F8: HSBC ASSET MANAGEMENT INDIA PVT Ltd | G8: HSBC Midcap Fund Growth | H8: 5572421/08 | I8: 107.92 | J8: 43955 | K8: N | L8: 30000 | M8: 0 | N8: 277.984 | O8: Executed | Q8: Web
A9: Arun Venkatesan | B9: ICICI | C9: 43978 | D9: 89984464 | E9: Div-Reinvestment | F9: HDFC ASSET MANAGEMENT COMPANY LIMITED | G9: HDFC Balanced Advantage Fund - Regular Plan - IDCW | H9: 16747427/33 | I9: 18.888 | J9: 43978 | K9: Y | L9: 294.21 | M9: 0 | N9: 15.577 | O9: Executed | Q9: SYS
A10: Arun Venkatesan | B10: ICICI | C10: 44005 | D10: 90833658 | E10: Purchase | F10: AXIS ASSET MANAGEMENT COMPANY LIMITED | G10: Axis Midcap Fund - Growth | H10: 91087813195 | I10: 38.01 | J10: 44005 | K10: N | L10: 40000 | M10: 0 | N10: 1052.355 | O10: Executed | Q10: Web
A11: Arun Venkatesan | B11: ICICI | C11: 44006 | D11: 90837474 | E11: Purchase-SIP | F11: ICICI PRUDENTIAL MUTUAL FUND | G11: ICICI Prudential Multi-Asset Fund - IDCW | H11: 15070068/41 | I11: 16.7906 | J11: 44006 | K11: N | L11: 5000 | M11: 0 | N11: 297.786 | O11: Executed | Q11: SYS
A12: Arun Venkatesan | B12: ICICI | C12: 44008 | D12: 90992226 | E12: Div-Reinvestment | F12: HDFC ASSET MANAGEMENT COMPANY LIMITED | G12: HDFC Balanced Advantage Fund - Regular Plan - IDCW | H12: 16747427/33 | I12: 21.051 | J12: 44008 | K12: Y | L12: 297.79 | M12: 0 | N12: 14.146 | O12: Executed | Q12: SYS
A13: Arun Venkatesan | B13: ICICI | C13: 44010 | D13: 90987394 | E13: Purchase-SIP | F13: HDFC ASSET MANAGEMENT COMPANY LIMITED | G13: HDFC Balanced Advantage Fund - Regular Plan - IDCW | H13: 16747427/33 | I13: 20.843 | J13: 44011 | K13: Y | L13: 5000 | M13: 0 | N13: 239.889 | O13: Executed | Q13: SYS
A14: Arun Venkatesan | B14: ICICI | C14: 44012 | D14: 91035580 | E14: Purchase | F14: ICICI PRUDENTIAL MUTUAL FUND | G14: ICICI Prudential Midcap Fund - Growth | H14: 15070068/41 | I14: 78.47 | J14: 44012 | K14: N | L14: 0 | M14: 0 | N14: 318.593 | O14: Executed | Q14: Web
A15: Arun Venkatesan | B15: ICICI | C15: 44015 | D15: 91289318 | E15: Div-Reinvestment | F15: ICICI PRUDENTIAL MUTUAL FUND | G15: ICICI Prudential Multi-Asset Fund - IDCW | H15: 15070068/41 | I15: 16.8552 | J15: 44015 | K15: N | L15: 47.65 | M15: 0 | N15: 2.827 | O15: Executed | Q15: SYS
A16: Arun Venkatesan | B16: ICICI | C16: 44036 | D16: 91940347 | E16: Purchase-SIP | F16: ICICI PRUDENTIAL MUTUAL FUND | G16: ICICI Prudential Multi-Asset Fund - IDCW | H16: 15070068/41 | I16: 17.2364 | J16: 44036 | K16: N | L16: 5000 | M16: 0 | N16: 290.069 | O16: Executed | Q16: SYS
A17: Arun Venkatesan | B17: ICICI | C17: 44040 | D17: 92063258 | E17: Purchase-SIP | F17: HDFC ASSET MANAGEMENT COMPANY LIMITED | G17: HDFC Balanced Advantage Fund - Regular Plan - IDCW | H17: 16747427/33 | I17: 21.398 | J17: 44040 | K17: Y | L17: 5000 | M17: 0 | N17: 233.655 | O17: Executed | Q17: SYS
A18: Arun Venkatesan | B18: ICICI | C18: 44040 | D18: 92100713 | E18: Div-Reinvestment | F18: HDFC ASSET MANAGEMENT COMPANY LIMITED | G18: HDFC Balanced Advantage Fund - Regular Plan - IDCW | H18: 16747427/33 | I18: 21.317 | J18: 44040 | K18: Y | L18: 356.2 | M18: 0 | N18: 16.71 | O18: Executed | Q18: SYS
A19: Arun Venkatesan | B19: ICICI | C19: 44048 | D19: 92385427 | E19: Div-Reinvestment | F19: ICICI PRUDENTIAL MUTUAL FUND | G19: ICICI Prudential Multi-Asset Fund - IDCW | H19: 15070068/41 | I19: 17.2249 | J19: 44048 | K19: N | L19: 94.51 | M19: 0 | N19: 5.487 | O19: Executed | Q19: SYS
A20: Arun Venkatesan | B20: ICICI | C20: 44061 | D20: 92834291 | E20: Purchase | F20: AXIS ASSET MANAGEMENT COMPANY LIMITED | G20: AXIS LARGE CAP FUND - Growth | H20: 91087813195 | I20: 30.98 | J20: 44062 | K20: N | L20: 25000 | M20: 0 | N20: 806.932 | O20: Executed | Q20: Web
A21: Arun Venkatesan | B21: ICICI | C21: 44067 | D21: 93011188 | E21: Purchase-SIP | F21: ICICI PRUDENTIAL MUTUAL FUND | G21: ICICI Prudential Multi-Asset Fund - IDCW | H21: 15070068/41 | I21: 18.049 | J21: 44067 | K21: N | L21: 5000 | M21: 0 | N21: 277.01 | O21: Executed | Q21: SYS
A22: Arun Venkatesan | B22: ICICI | C22: 44069 | D22: 93141330 | E22: Div-Reinvestment | F22: HDFC ASSET MANAGEMENT COMPANY LIMITED | G22: HDFC Balanced Advantage Fund - Regular Plan - IDCW | H22: 16747427/33 | I22: 22.479 | J22: 44069 | K22: Y | L22: 413.78 | M22: 0 | N22: 18.407 | O22: Executed | Q22: SYS
A23: Arun Venkatesan | B23: ICICI | C23: 44071 | D23: 93178156 | E23: Purchase-SIP | F23: HDFC ASSET MANAGEMENT COMPANY LIMITED | G23: HDFC Balanced Advantage Fund - Regular Plan - IDCW | H23: 16747427/33 | I23: 22.759 | J23: 44071 | K23: Y | L23: 5000 | M23: 0 | N23: 219.682 | O23: Executed | Q23: SYS
A24: Arun Venkatesan | B24: ICICI | C24: 44098 | D24: 94111638 | E24: Purchase-SIP | F24: ICICI PRUDENTIAL MUTUAL FUND | G24: ICICI Prudential Multi-Asset Fund - IDCW | H24: 15070068/41 | I24: 16.0465 | J24: 44098 | K24: N | L24: 5000 | M24: 0 | N24: 311.579 | O24: Executed | Q24: SYS
A25: Arun Venkatesan | B25: ICICI | C25: 44100 | D25: 94260425 | E25: Div-Reinvestment | F25: HDFC ASSET MANAGEMENT COMPANY LIMITED | G25: HDFC Balanced Advantage Fund - Regular Plan - IDCW | H25: 16747427/33 | I25: 20.408 | J25: 44100 | K25: Y | L25: 468.54 | M25: 0 | N25: 22.959 | O25: Executed | Q25: SYS
A26: Arun Venkatesan | B26: ICICI | C26: 44102 | D26: 94244967 | E26: Purchase-SIP | F26: HDFC ASSET MANAGEMENT COMPANY LIMITED | G26: HDFC Balanced Advantage Fund - Regular Plan - IDCW | H26: 16747427/33 | I26: 20.808 | J26: 44102 | K26: Y | L26: 5000 | M26: 0 | N26: 240.28 | O26: Executed | Q26: SYS
A27: Arun Venkatesan | B27: ICICI | C27: 44119 | D27: 94940735 | E27: Purchase | F27: HSBC ASSET MANAGEMENT INDIA PVT Ltd | G27: HSBC Midcap Fund IDCW | H27: 5572421/08 | I27: 37.56 | J27: 44119 | K27: N | L27: 200000 | M27: 0 | N27: 5324.547 | O27: Executed | Q27: Web
A28: Arun Venkatesan | B28: ICICI | C28: 44124 | D28: 95075300 | E28: Purchase | F28: ADITYA BIRLA SUN LIFE ASSET MANAGEMENT COMPANY LTD | G28: Aditya Birla Sun Life Savings Fund - Growth | H28: 1039297412 | I28: 415.5092 | J28: 44124 | K28: N | L28: 100000 | M28: 0 | N28: 240.657 | O28: Executed | Q28: Web
A29: Arun Venkatesan | B29: ICICI | C29: 44124 | D29: 95075348 | E29: Redemption | F29: ADITYA BIRLA SUN LIFE ASSET MANAGEMENT COMPANY LTD | G29: ADITYA BIRLA SUN LIFE ELSS TAX SAVER FUND - IDCW | H29: 1039297412 | I29: 0 | J29: 46007 | K29: N | L29: 0 | M29: 0 | N29: 0 | O29: Rejected | Q29: Web
A30: Arun Venkatesan | B30: ICICI | C30: 44128 | D30: 95174584 | E30: Purchase-SIP | F30: ICICI PRUDENTIAL MUTUAL FUND | G30: ICICI Prudential Multi-Asset Fund - IDCW | H30: 15070068/41 | I30: 16.5502 | J30: 44130 | K30: N | L30: 5000 | M30: 0 | N30: 302.096 | O30: Executed | Q30: SYS
A31: Arun Venkatesan | B31: ICICI | C31: 44131 | D31: 95307503 | E31: Div-Reinvestment | F31: HDFC ASSET MANAGEMENT COMPANY LIMITED | G31: HDFC Balanced Advantage Fund - Regular Plan - IDCW | H31: 16747427/33 | I31: 21.028 | J31: 44131 | K31: Y | L31: 529.08 | M31: 0 | N31: 25.161 | O31: Executed | Q31: SYS
A32: Arun Venkatesan | B32: ICICI | C32: 44132 | D32: 95303782 | E32: Purchase-SIP | F32: HDFC ASSET MANAGEMENT COMPANY LIMITED | G32: HDFC Balanced Advantage Fund - Regular Plan - IDCW | H32: 16747427/33 | I32: 20.927 | J32: 44132 | K32: Y | L32: 5000 | M32: 0 | N32: 238.914 | O32: Executed | Q32: SYS
A33: Arun Venkatesan | B33: ICICI | C33: 44137 | D33: 95474589 | E33: Purchase | F33: MIRAE ASSET GLOBAL INVESTMENT MGMT INDIA P LTD | G33: MIRAE ASSET ESG SECTOR LEADERS ETF - REGULAR GROWTH | H33: 79932348715 | I33: 22.345 | J33: 44152 | K33: N | L33: 200000 | M33: 0 | N33: 8950 | O33: Executed | Q33: Web
A34: Arun Venkatesan | B34: ICICI | C34: 44148 | D34: 95920767 | E34: Purchase | F34: ICICI PRUDENTIAL MUTUAL FUND | G34: ICICI Prudential Esg Exclusionary Strategy Fund Growth | H34: 15070068/41 | I34: 0 | J34: 46007 | K34: N | L34: 100000 | M34: 0 | N34: 0 | O34: Cancelled | Q34: Web
A35: Arun Venkatesan | B35: ICICI | C35: 44148 | D35: 95920772 | E35: Purchase | F35: ICICI PRUDENTIAL MUTUAL FUND | G35: ICICI Prudential Esg Exclusionary Strategy Fund Growth | H35: 15070068/41 | I35: 10.58 | J35: 44148 | K35: N | L35: 100000 | M35: 0 | N35: 9451.323 | O35: Executed | Q35: Web
A36: Arun Venkatesan | B36: ICICI | C36: 44152 | D36: 96833552 | E36: TO | F36: MIRAE ASSET GLOBAL INVESTMENT MGMT INDIA P LTD | G36: MIRAE ASSET ESG SECTOR LEADERS ETF - REGULAR GROWTH | H36: 79932348715 | I36: 22.345 | J36: 44152 | K36: N | L36: 199990 | M36: 0 | N36: 8950 | O36: Executed | Q36: SYS
A37: Arun Venkatesan | B37: ICICI | C37: 44159 | D37: 96265204 | E37: Purchase-SIP | F37: ICICI PRUDENTIAL MUTUAL FUND | G37: ICICI Prudential Multi-Asset Fund - IDCW | H37: 15070068/41 | I37: 17.8105 | J37: 44159 | K37: N | L37: 5000 | M37: 0 | N37: 280.719 | O37: Executed | Q37: SYS
A38: Arun Venkatesan | B38: ICICI | C38: 44161 | D38: 96392184 | E38: Div-Reinvestment | F38: HDFC ASSET MANAGEMENT COMPANY LIMITED | G38: HDFC Balanced Advantage Fund - Regular Plan - IDCW | H38: 16747427/33 | I38: 23.113 | J38: 44161 | K38: Y | L38: 589.81 | M38: 0 | N38: 25.519 | O38: Executed | Q38: SYS
A39: Arun Venkatesan | B39: ICICI | C39: 44163 | D39: 96432721 | E39: Purchase-SIP | F39: HDFC ASSET MANAGEMENT COMPANY LIMITED | G39: HDFC Balanced Advantage Fund - Regular Plan - IDCW | H39: 16747427/33 | I39: 23.504 | J39: 44166 | K39: Y | L39: 5000 | M39: 0 | N39: 212.719 | O39: Executed | Q39: SYS
A40: Arun Venkatesan | B40: ICICI | C40: 44189 | D40: 97448198 | E40: Purchase-SIP | F40: ICICI PRUDENTIAL MUTUAL FUND | G40: ICICI Prudential Multi-Asset Fund - IDCW | H40: 15070068/41 | I40: 19.0908 | J40: 44189 | K40: N | L40: 5000 | M40: 0 | N40: 261.893 | O40: Executed | Q40: SYS
...

Sheet Mutual Fund Dividend
A1: Person | B1: Account | C1: AMC Name | D1: Scheme Name | E1: Record Date | F1: Dividend Per Unit(Rs./Unit) | G1: NAV as on Record Date | H1: Gross Amount(rs.) | I1: Units | J1: Dividend Type | K1: Missing Date
A2: Arun Venkatesan | B2: ICICI | C2: ADITYA BIRLA SUN LIFE ASSET MANAGEMENT COMPANY LTD | D2: ADITYA BIRLA SUN LIFE ELSS TAX SAVER FUND - IDCW | E2: 43798 | F2: 0 | G2: 153.16 | H2: 277.26 | I2: 0 | J2: DP
A3: Arun Venkatesan | B3: ICICI | C3: HDFC ASSET MANAGEMENT COMPANY LIMITED | D3: HDFC Balanced Advantage Fund - Regular Plan - IDCW | E3: 43949 | F3: 0 | G3: 19.803 | H3: 55.47 | I3: 2.801 | J3: DR | K3: {=_xlfn.XLOOKUP( 1, ('Mutual Fund Transaction'!G:G='Mutual Fund Dividend'!D144) * ('Mutual Fund Transaction'!L:L='Mutual Fund Dividend'!H144) * ('Mutual Fund Transaction'!N:N='Mutual Fund Dividend'!I144), 'Mutual Fund Transaction'!C:C, "" )}
A4: Arun Venkatesan | B4: ICICI | C4: HDFC ASSET MANAGEMENT COMPANY LIMITED | D4: HDFC Balanced Advantage Fund - Regular Plan - IDCW | E4: 43978 | F4: 0 | G4: 18.888 | H4: 294.21 | I4: 15.577 | J4: DR | K4: {=_xlfn.XLOOKUP( 1, ('Mutual Fund Transaction'!G:G='Mutual Fund Dividend'!D143) * ('Mutual Fund Transaction'!L:L='Mutual Fund Dividend'!H143) * ('Mutual Fund Transaction'!N:N='Mutual Fund Dividend'!I143), 'Mutual Fund Transaction'!C:C, "" )} -> 45987
A5: Arun Venkatesan | B5: ICICI | C5: HDFC ASSET MANAGEMENT COMPANY LIMITED | D5: HDFC Balanced Advantage Fund - Regular Plan - IDCW | E5: 44008 | F5: 0 | G5: 21.051 | H5: 297.79 | I5: 14.146 | J5: DR | K5: {=_xlfn.XLOOKUP( 1, ('Mutual Fund Transaction'!G:G='Mutual Fund Dividend'!D142) * ('Mutual Fund Transaction'!L:L='Mutual Fund Dividend'!H142) * ('Mutual Fund Transaction'!N:N='Mutual Fund Dividend'!I142), 'Mutual Fund Transaction'!C:C, "" )}
A6: Arun Venkatesan | B6: ICICI | C6: ICICI PRUDENTIAL MUTUAL FUND | D6: ICICI Prudential Multi-Asset Fund - IDCW | E6: 44015 | F6: 0 | G6: 16.8552 | H6: 47.65 | I6: 2.827 | J6: DR | K6: {=_xlfn.XLOOKUP( 1, ('Mutual Fund Transaction'!G:G='Mutual Fund Dividend'!D141) * ('Mutual Fund Transaction'!L:L='Mutual Fund Dividend'!H141) * ('Mutual Fund Transaction'!N:N='Mutual Fund Dividend'!I141), 'Mutual Fund Transaction'!C:C, "" )} -> 45958
A7: Arun Venkatesan | B7: ICICI | C7: HDFC ASSET MANAGEMENT COMPANY LIMITED | D7: HDFC Balanced Advantage Fund - Regular Plan - IDCW | E7: 44040 | F7: 0 | G7: 21.317 | H7: 356.2 | I7: 16.71 | J7: DR | K7: {=_xlfn.XLOOKUP( 1, ('Mutual Fund Transaction'!G:G='Mutual Fund Dividend'!D140) * ('Mutual Fund Transaction'!L:L='Mutual Fund Dividend'!H140) * ('Mutual Fund Transaction'!N:N='Mutual Fund Dividend'!I140), 'Mutual Fund Transaction'!C:C, "" )}
A8: Arun Venkatesan | B8: ICICI | C8: ICICI PRUDENTIAL MUTUAL FUND | D8: ICICI Prudential Multi-Asset Fund - IDCW | E8: 44048 | F8: 0 | G8: 17.2249 | H8: 94.51 | I8: 5.487 | J8: DR | K8: {=_xlfn.XLOOKUP( 1, ('Mutual Fund Transaction'!G:G='Mutual Fund Dividend'!D139) * ('Mutual Fund Transaction'!L:L='Mutual Fund Dividend'!H139) * ('Mutual Fund Transaction'!N:N='Mutual Fund Dividend'!I139), 'Mutual Fund Transaction'!C:C, "" )} -> 45926
A9: Arun Venkatesan | B9: ICICI | C9: HDFC ASSET MANAGEMENT COMPANY LIMITED | D9: HDFC Balanced Advantage Fund - Regular Plan - IDCW | E9: 44069 | F9: 0 | G9: 22.479 | H9: 413.78 | I9: 18.407 | J9: DR | K9: {=_xlfn.XLOOKUP( 1, ('Mutual Fund Transaction'!G:G='Mutual Fund Dividend'!D138) * ('Mutual Fund Transaction'!L:L='Mutual Fund Dividend'!H138) * ('Mutual Fund Transaction'!N:N='Mutual Fund Dividend'!I138), 'Mutual Fund Transaction'!C:C, "" )}
A10: Arun Venkatesan | B10: ICICI | C10: ICICI PRUDENTIAL MUTUAL FUND | D10: ICICI Prudential Multi-Asset Fund - IDCW | E10: 44082 | F10: 0 | G10: 17.2545 | H10: 139.71 | I10: 0 | J10: DP
A11: Arun Venkatesan | B11: ICICI | C11: HDFC ASSET MANAGEMENT COMPANY LIMITED | D11: HDFC Balanced Advantage Fund - Regular Plan - IDCW | E11: 44100 | F11: 0 | G11: 20.408 | H11: 468.54 | I11: 22.959 | J11: DR | K11: {=_xlfn.XLOOKUP( 1, ('Mutual Fund Transaction'!G:G='Mutual Fund Dividend'!D137) * ('Mutual Fund Transaction'!L:L='Mutual Fund Dividend'!H137) * ('Mutual Fund Transaction'!N:N='Mutual Fund Dividend'!I137), 'Mutual Fund Transaction'!C:C, "" )} -> 45895
A12: Arun Venkatesan | B12: ICICI | C12: ICICI PRUDENTIAL MUTUAL FUND | D12: ICICI Prudential Multi-Asset Fund - IDCW | E12: 44109 | F12: 0 | G12: 16.7074 | H12: 189.56 | I12: 0 | J12: DP
A13: Arun Venkatesan | B13: ICICI | C13: HDFC ASSET MANAGEMENT COMPANY LIMITED | D13: HDFC Balanced Advantage Fund - Regular Plan - IDCW | E13: 44131 | F13: 0 | G13: 21.028 | H13: 529.08 | I13: 25.161 | J13: DR | K13: {=_xlfn.XLOOKUP( 1, ('Mutual Fund Transaction'!G:G='Mutual Fund Dividend'!D136) * ('Mutual Fund Transaction'!L:L='Mutual Fund Dividend'!H136) * ('Mutual Fund Transaction'!N:N='Mutual Fund Dividend'!I136), 'Mutual Fund Transaction'!C:C, "" )}
A14: Arun Venkatesan | B14: ICICI | C14: ICICI PRUDENTIAL MUTUAL FUND | D14: ICICI Prudential Multi-Asset Fund - IDCW | E14: 44137 | F14: 0 | G14: 16.6284 | H14: 237.9 | I14: 0 | J14: DP
A15: Arun Venkatesan | B15: ICICI | C15: ADITYA BIRLA SUN LIFE ASSET MANAGEMENT COMPANY LTD | D15: ADITYA BIRLA SUN LIFE ELSS TAX SAVER FUND - IDCW | E15: 44160 | F15: 0 | G15: 149.92 | H15: 242.61 | I15: 0 | J15: DP
A16: Arun Venkatesan | B16: ICICI | C16: HDFC ASSET MANAGEMENT COMPANY LIMITED | D16: HDFC Balanced Advantage Fund - Regular Plan - IDCW | E16: 44161 | F16: 0 | G16: 23.113 | H16: 589.81 | I16: 25.519 | J16: DR | K16: {=_xlfn.XLOOKUP( 1, ('Mutual Fund Transaction'!G:G='Mutual Fund Dividend'!D135) * ('Mutual Fund Transaction'!L:L='Mutual Fund Dividend'!H135) * ('Mutual Fund Transaction'!N:N='Mutual Fund Dividend'!I135), 'Mutual Fund Transaction'!C:C, "" )}
A17: Arun Venkatesan | B17: ICICI | C17: ICICI PRUDENTIAL MUTUAL FUND | D17: ICICI Prudential Multi-Asset Fund - IDCW | E17: 44167 | F17: 0 | G17: 18.259 | H17: 282.81 | I17: 0 | J17: DP
A18: Arun Venkatesan | B18: ICICI | C18: HDFC ASSET MANAGEMENT COMPANY LIMITED | D18: HDFC Balanced Advantage Fund - Regular Plan - IDCW | E18: 44194 | F18: 0 | G18: 24.85 | H18: 690.49 | I18: 27.785 | J18: DR | K18: {=_xlfn.XLOOKUP( 1, ('Mutual Fund Transaction'!G:G='Mutual Fund Dividend'!D134) * ('Mutual Fund Transaction'!L:L='Mutual Fund Dividend'!H134) * ('Mutual Fund Transaction'!N:N='Mutual Fund Dividend'!I134), 'Mutual Fund Transaction'!C:C, "" )} -> 45864
A19: Arun Venkatesan | B19: ICICI | C19: ICICI PRUDENTIAL MUTUAL FUND | D19: ICICI Prudential Multi-Asset Fund - IDCW | E19: 44200 | F19: 0 | G19: 19.5936 | H19: 324.71 | I19: 0 | J19: DP
A20: Arun Venkatesan | B20: ICICI | C20: HDFC ASSET MANAGEMENT COMPANY LIMITED | D20: HDFC Balanced Advantage Fund - Regular Plan - IDCW | E20: 44222 | F20: 0 | G20: 25.074 | H20: 371.88 | I20: 14.831 | J20: DR | K20: {=_xlfn.XLOOKUP( 1, ('Mutual Fund Transaction'!G:G='Mutual Fund Dividend'!D133) * ('Mutual Fund Transaction'!L:L='Mutual Fund Dividend'!H133) * ('Mutual Fund Transaction'!N:N='Mutual Fund Dividend'!I133), 'Mutual Fund Transaction'!C:C, "" )}
A21: Arun Venkatesan | B21: ICICI | C21: ICICI PRUDENTIAL MUTUAL FUND | D21: ICICI Prudential Multi-Asset Fund - IDCW | E21: 44229 | F21: 0 | G21: 19.9224 | H21: 339.11 | I21: 0 | J21: DP
A22: Arun Venkatesan | B22: ICICI | C22: HDFC ASSET MANAGEMENT COMPANY LIMITED | D22: HDFC Balanced Advantage Fund - Regular Plan - IDCW | E22: 44253 | F22: 0 | G22: 27.677 | H22: 690.69 | I22: 24.954 | J22: DR | K22: {=_xlfn.XLOOKUP( 1, ('Mutual Fund Transaction'!G:G='Mutual Fund Dividend'!D132) * ('Mutual Fund Transaction'!L:L='Mutual Fund Dividend'!H132) * ('Mutual Fund Transaction'!N:N='Mutual Fund Dividend'!I132), 'Mutual Fund Transaction'!C:C, "" )} -> 45834
A23: Arun Venkatesan | B23: ICICI | C23: ICICI PRUDENTIAL MUTUAL FUND | D23: ICICI Prudential Multi-Asset Fund - IDCW | E23: 44257 | F23: 0 | G23: 21.132 | H23: 374.31 | I23: 0 | J23: DP
A24: Arun Venkatesan | B24: ICICI | C24: HDFC ASSET MANAGEMENT COMPANY LIMITED | D24: HDFC Balanced Advantage Fund - Regular Plan - IDCW | E24: 44281 | F24: 0 | G24: 25.886 | H24: 734.47 | I24: 28.372 | J24: DR | K24: {=_xlfn.XLOOKUP( 1, ('Mutual Fund Transaction'!G:G='Mutual Fund Dividend'!D131) * ('Mutual Fund Transaction'!L:L='Mutual Fund Dividend'!H131) * ('Mutual Fund Transaction'!N:N='Mutual Fund Dividend'!I131), 'Mutual Fund Transaction'!C:C, "" )}
A25: Arun Venkatesan | B25: ICICI | C25: ICICI PRUDENTIAL MUTUAL FUND | D25: ICICI Prudential Multi-Asset Fund - IDCW | E25: 44292 | F25: 0 | G25: 20.5283 | H25: 443.78 | I25: 0 | J25: DP
A26: Arun Venkatesan | B26: ICICI | C26: HDFC ASSET MANAGEMENT COMPANY LIMITED | D26: HDFC Balanced Advantage Fund - Regular Plan - IDCW | E26: 44313 | F26: 0 | G26: 25.696 | H26: 844.68 | I26: 32.87 | J26: DR | K26: {=_xlfn.XLOOKUP( 1, ('Mutual Fund Transaction'!G:G='Mutual Fund Dividend'!D130) * ('Mutual Fund Transaction'!L:L='Mutual Fund Dividend'!H130) * ('Mutual Fund Transaction'!N:N='Mutual Fund Dividend'!I130), 'Mutual Fund Transaction'!C:C, "" )} -> 45804
A27: Arun Venkatesan | B27: ICICI | C27: ICICI PRUDENTIAL MUTUAL FUND | D27: ICICI Prudential Multi-Asset Fund - IDCW | E27: 44319 | F27: 0 | G27: 20.7274 | H27: 483.22 | I27: 0 | J27: DP
A28: Arun Venkatesan | B28: ICICI | C28: HDFC ASSET MANAGEMENT COMPANY LIMITED | D28: HDFC Balanced Advantage Fund - Regular Plan - IDCW | E28: 44342 | F28: 0 | G28: 27.676 | H28: 896.3 | I28: 32.384 | J28: DR | K28: {=_xlfn.XLOOKUP( 1, ('Mutual Fund Transaction'!G:G='Mutual Fund Dividend'!D129) * ('Mutual Fund Transaction'!L:L='Mutual Fund Dividend'!H129) * ('Mutual Fund Transaction'!N:N='Mutual Fund Dividend'!I129), 'Mutual Fund Transaction'!C:C, "" )}
A29: Arun Venkatesan | B29: ICICI | C29: ICICI PRUDENTIAL MUTUAL FUND | D29: ICICI Prudential Multi-Asset Fund - IDCW | E29: 44348 | F29: 0 | G29: 21.7737 | H29: 520.33 | I29: 0 | J29: DP
A30: Arun Venkatesan | B30: ICICI | C30: HDFC ASSET MANAGEMENT COMPANY LIMITED | D30: HDFC Balanced Advantage Fund - Regular Plan - IDCW | E30: 44373 | F30: 0 | G30: 28.136 | H30: 945.19 | I30: 33.592 | J30: DR | K30: {=_xlfn.XLOOKUP( 1, ('Mutual Fund Transaction'!G:G='Mutual Fund Dividend'!D128) * ('Mutual Fund Transaction'!L:L='Mutual Fund Dividend'!H128) * ('Mutual Fund Transaction'!N:N='Mutual Fund Dividend'!I128), 'Mutual Fund Transaction'!C:C, "" )} -> 45773
A31: Arun Venkatesan | B31: ICICI | C31: ICICI PRUDENTIAL MUTUAL FUND | D31: ICICI Prudential Multi-Asset Fund - IDCW | E31: 44378 | F31: 0 | G31: 21.7673 | H31: 557.08 | I31: 0 | J31: DP
A32: Arun Venkatesan | B32: ICICI | C32: HDFC ASSET MANAGEMENT COMPANY LIMITED | D32: HDFC Balanced Advantage Fund - Regular Plan - IDCW | E32: 44404 | F32: 0 | G32: 28.31 | H32: 993.73 | I32: 35.1 | J32: DR | K32: {=_xlfn.XLOOKUP( 1, ('Mutual Fund Transaction'!G:G='Mutual Fund Dividend'!D127) * ('Mutual Fund Transaction'!L:L='Mutual Fund Dividend'!H127) * ('Mutual Fund Transaction'!N:N='Mutual Fund Dividend'!I127), 'Mutual Fund Transaction'!C:C, "" )}
A33: Arun Venkatesan | B33: ICICI | C33: ICICI PRUDENTIAL MUTUAL FUND | D33: ICICI Prudential Multi-Asset Fund - IDCW | E33: 44411 | F33: 0 | G33: 22.5292 | H33: 593.56 | I33: 0 | J33: DP
A34: Arun Venkatesan | B34: ICICI | C34: L&T ASSET MANAGEMENT COMPANY | D34: LNT Mid Cap Fund-Regular Plan-IDCW | E34: 44434 | F34: 0 | G34: 55.09 | H34: 16771.91 | I34: 0 | J34: DP
A35: Arun Venkatesan | B35: ICICI | C35: HDFC ASSET MANAGEMENT COMPANY LIMITED | D35: HDFC Balanced Advantage Fund - Regular Plan - IDCW | E35: 44434 | F35: 0 | G35: 27.806 | H35: 570.64 | I35: 20.521 | J35: DR | K35: {=_xlfn.XLOOKUP( 1, ('Mutual Fund Transaction'!G:G='Mutual Fund Dividend'!D126) * ('Mutual Fund Transaction'!L:L='Mutual Fund Dividend'!H126) * ('Mutual Fund Transaction'!N:N='Mutual Fund Dividend'!I126), 'Mutual Fund Transaction'!C:C, "" )} -> 45742
A36: Arun Venkatesan | B36: ICICI | C36: ICICI PRUDENTIAL MUTUAL FUND | D36: ICICI Prudential Multi-Asset Fund - IDCW | E36: 44440 | F36: 0 | G36: 22.8851 | H36: 629.42 | I36: 0 | J36: DP
A37: Arun Venkatesan | B37: ICICI | C37: HDFC ASSET MANAGEMENT COMPANY LIMITED | D37: HDFC Balanced Advantage Fund - Regular Plan - IDCW | E37: 44467 | F37: 0 | G37: 29.068 | H37: 979.03 | I37: 33.679 | J37: DR | K37: {=_xlfn.XLOOKUP( 1, ('Mutual Fund Transaction'!G:G='Mutual Fund Dividend'!D125) * ('Mutual Fund Transaction'!L:L='Mutual Fund Dividend'!H125) * ('Mutual Fund Transaction'!N:N='Mutual Fund Dividend'!I125), 'Mutual Fund Transaction'!C:C, "" )}
A38: Arun Venkatesan | B38: ICICI | C38: ICICI PRUDENTIAL MUTUAL FUND | D38: ICICI Prudential Multi-Asset Fund - IDCW | E38: 44474 | F38: 0 | G38: 24.4148 | H38: 663.35 | I38: 0 | J38: DP
A39: Arun Venkatesan | B39: ICICI | C39: HDFC ASSET MANAGEMENT COMPANY LIMITED | D39: HDFC Balanced Advantage Fund - Regular Plan - IDCW | E39: 44495 | F39: 0 | G39: 30.065 | H39: 1155.06 | I39: 38.417 | J39: DR | K39: {=_xlfn.XLOOKUP( 1, ('Mutual Fund Transaction'!G:G='Mutual Fund Dividend'!D124) * ('Mutual Fund Transaction'!L:L='Mutual Fund Dividend'!H124) * ('Mutual Fund Transaction'!N:N='Mutual Fund Dividend'!I124), 'Mutual Fund Transaction'!C:C, "" )} -> 45714
A40: Arun Venkatesan | B40: ICICI | C40: ICICI PRUDENTIAL MUTUAL FUND | D40: ICICI Prudential Multi-Asset Fund - IDCW | E40: 44501 | F40: 0 | G40: 24.5488 | H40: 237.69 | I40: 0 | J40: DP
...

Sheet LIC
A1: Person | B1: Policy No | C1: Agency Code | D1: Premium Due Date | E1: Paid on | F1: Transaction No | G1: Transaction Type | H1: Premium Amount | I1: Late Fee | J1: Total Amount | K1: Benefit Amount
A2: Arun Venkatesan | B2: 734747593 | C2: 2093733 | D2: 39441 | G2: Contribution | H2: 12209 | J2: 12209
A3: Arun Venkatesan | B3: 734747593 | C3: 2093733 | D3: 39624 | G3: Contribution | H3: 12209 | J3: 12209
A4: Arun Venkatesan | B4: 734747593 | C4: 2093733 | D4: 39807 | G4: Contribution | H4: 12209 | J4: 12209
A5: Arun Venkatesan | B5: 734747593 | C5: 2093733 | D5: 39989 | G5: Contribution | H5: 12209 | J5: 12209
A6: Arun Venkatesan | B6: 734747593 | C6: 2093733 | D6: 40172 | G6: Contribution | H6: 12209 | J6: 12209
A7: Arun Venkatesan | B7: 734747593 | C7: 2093733 | D7: 40354 | E7: 40478 | F7: PR0227127800011011 | G7: Contribution | H7: 12209 | I7: 325.6 | J7: 12534.6
A8: Arun Venkatesan | B8: 734747593 | C8: 2093733 | D8: 40537 | E8: 40540 | F8: PR0315311800011011 | G8: Contribution | H8: 12209 | I8: 0 | J8: 12209
A9: Arun Venkatesan | B9: 734747593 | C9: 2093733 | D9: 40719 | E9: 40724 | F9: PR0627595700011112 | G9: Contribution | H9: 12209 | I9: 0 | J9: 12209
A10: Arun Venkatesan | B10: 734747593 | D10: 40858 | E10: 40858 | G10: Benefit | K10: 70000
A11: Arun Venkatesan | B11: 734747593 | C11: 2093733 | D11: 40902 | E11: 40919 | F11: PR1024166300011112 | G11: Contribution | H11: 12209 | I11: 0 | J11: 12209
A12: Arun Venkatesan | B12: 734747593 | C12: 2093733 | D12: 41085 | E12: 41162 | F12: PR0376500200011213 | G12: Contribution | H12: 12209 | I12: 290 | J12: 12499
A13: Arun Venkatesan | B13: 734747593 | C13: 2093733 | D13: 41268 | E13: 41318 | F13: PR0828455100011213 | G13: Contribution | H13: 12209 | I13: 193.3 | J13: 12402.3
A14: Arun Venkatesan | B14: 734747593 | C14: 2093733 | D14: 41450 | E14: 41486 | F14: PR0320070200011314 | G14: Contribution | H14: 12209 | I14: 96.7 | J14: 12305.7
A15: Arun Venkatesan | B15: 734747593 | C15: 2093733 | D15: 41633 | E15: 41647 | F15: PR0911831300011314 | G15: Contribution | H15: 12209 | I15: 0 | J15: 12209
A16: Arun Venkatesan | B16: 734747593 | C16: 2093733 | D16: 41815 | E16: 41830 | F16: PR0337184600011415 | G16: Contribution | H16: 12209 | I16: 0 | J16: 12209
A17: Arun Venkatesan | B17: 734747593 | C17: 2093733 | D17: 41998 | E17: 41990 | F17: PR1003477000011415 | G17: Contribution | H17: 12209 | I17: 0 | J17: 12209
A18: Arun Venkatesan | B18: 734747593 | C18: 2093733 | D18: 42180 | E18: 42207 | F18: PR0441696100011516 | G18: Contribution | H18: 12209 | I18: 0 | J18: 12209
A19: Arun Venkatesan | B19: 734747593 | D19: 42326 | E19: 42326 | G19: Benefit | K19: 70000
A20: Arun Venkatesan | B20: 734747593 | C20: 2093733 | D20: 42363 | E20: 42457 | F20: PR1663506300011516 | G20: Contribution | H20: 12209 | I20: 290 | J20: 12499
A21: Arun Venkatesan | B21: 734747593 | C21: 2093733 | D21: 42546 | E21: 42648 | F21: PR0837513400011617 | G21: Contribution | H21: 12209 | I21: 290 | J21: 12499
A22: Arun Venkatesan | B22: 734747593 | C22: 2093733 | D22: 42729 | G22: Contribution | H22: 12209 | I22: 0 | J22: 12209
A23: Arun Venkatesan | B23: 734747593 | C23: 2093733 | D23: 42911 | E23: 42948 | F23: PR0609717600011718 | G23: Contribution | H23: 12209 | I23: 96.7 | J23: 12305.7
A24: Arun Venkatesan | B24: 734747593 | C24: 2093733 | D24: 43094 | E24: 43137 | F24: PR1925027500011718 | G24: Contribution | H24: 12209 | I24: 96.7 | J24: 12305.7
A25: Arun Venkatesan | B25: 734747593 | C25: 2093733 | D25: 43276 | E25: 43308 | F25: PR0768348500011819 | G25: Contribution | H25: 12209 | I25: 96.7 | J25: 12305.7
A26: Arun Venkatesan | B26: 734747593 | C26: 2093733 | D26: 43459 | E26: 43468 | F26: PR1972146800011819 | G26: Contribution | H26: 12209 | I26: 0 | J26: 12209
A27: Arun Venkatesan | B27: 734747593 | C27: 2093733 | D27: 43641 | E27: 43654 | F27: PR0741573300011920 | G27: Contribution | H27: 12209 | I27: 0 | J27: 12209
A28: Arun Venkatesan | B28: 734747593 | D28: 43780 | E28: 43780 | G28: Benefit | K28: 70000
A29: Arun Venkatesan | B29: 734747593 | C29: 2093733 | D29: 43824 | E29: 43839 | F29: PR2321735300011920 | G29: Contribution | H29: 12209 | I29: 0 | J29: 12209
A30: Arun Venkatesan | B30: 734747593 | C30: 2093733 | D30: 44007 | E30: 44008 | G30: Contribution | H30: 12209 | I30: 0 | J30: 12209
A31: Arun Venkatesan | B31: 734747593 | C31: 2093733 | D31: 44190 | E31: 44228 | F31: PR3626845100012021 | G31: Contribution | H31: 12209 | I31: 77.36 | J31: 12286.36
A32: Arun Venkatesan | B32: 734747593 | C32: 2093733 | D32: 44372 | E32: 44355 | F32: PR0795036300012122 | G32: Contribution | H32: 12209 | I32: 0 | J32: 12209
A33: Arun Venkatesan | B33: 734747593 | C33: 2093733 | D33: 44555 | E33: 44590 | F33: PR3422682700012122 | G33: Contribution | H33: 12209 | I33: 96.7 | J33: 12305.7
A34: Arun Venkatesan | B34: 734747593 | C34: 2093733 | D34: 44737 | E34: 44764 | F34: PR1240784700012223 | G34: Contribution | H34: 12209 | I34: 0 | J34: 12209
A35: Arun Venkatesan | B35: 734747593 | C35: 2093733 | D35: 44920 | E35: 44936 | F35: PR3191769100012223 | G35: Contribution | H35: 12209 | I35: 0 | J35: 12209
A36: Arun Venkatesan | B36: 734747593 | C36: 2093733 | D36: 45102 | E36: 45141 | F36: PR1317778600012324 | G36: Contribution | H36: 12209 | I36: 96.7 | J36: 12305.7
A37: Arun Venkatesan | B37: 734747593 | D37: 45196 | E37: 45196 | G37: Benefit | K37: 70000
A38: Arun Venkatesan | B38: 734747593 | C38: 2093733 | D38: 45285 | E38: 45299 | F38: PR3161970100012324 | G38: Contribution | H38: 12209 | I38: 0 | J38: 12209
A39: Arun Venkatesan | B39: 734747593 | C39: 2093733 | D39: 45468 | E39: 45651 | F39: PR6323470200012425 | G39: Contribution | H39: 12209 | I39: 580 | J39: 12789
A40: Arun Venkatesan | B40: 734747593 | C40: 2093733 | D40: 45651 | E40: 45651 | F40: PR6323470200012425 | G40: Contribution | H40: 12209 | I40: 0 | J40: 12209
...

Sheet Providend Fund
A1: Person | B1: UAN | C1: Establishment Name | D1: Member ID | E1: Year | F1: Transaction Type | G1: Date | H1: Particulars | I1: Wages | J1: Contribution | K1: EPF Employee | L1: EPF Employer | M1: Pension
A2: Kurinji Malar Paranthaman | B2: 1.00199E+11 | C2: NTT DATA INFORMATION PROCESSING SERVICES PVT LTD | D2: TNAMB00483530000020685 | E2: 2013 | F2: Contribution | G2: 41479 | H2: Cont. For Due-Month 072013 | I2: 3241 | J2: 3241 | K2: 389 | L2: 119 | M2: 270
A3: Kurinji Malar Paranthaman | B3: 1.00199E+11 | C3: NTT DATA INFORMATION PROCESSING SERVICES PVT LTD | D3: TNAMB00483530000020685 | E3: 2013 | F3: Contribution | G3: 41520 | H3: Cont. For Due-Month 082013 | I3: 4476 | J3: 4476 | K3: 537 | L3: 164 | M3: 373
A4: Kurinji Malar Paranthaman | B4: 1.00199E+11 | C4: NTT DATA INFORMATION PROCESSING SERVICES PVT LTD | D4: TNAMB00483530000020685 | E4: 2013 | F4: Contribution | G4: 41540 | H4: Cont. For Due-Month 092013 | I4: 4630 | J4: 4630 | K4: 556 | L4: 170 | M4: 386
A5: Kurinji Malar Paranthaman | B5: 1.00199E+11 | C5: NTT DATA INFORMATION PROCESSING SERVICES PVT LTD | D5: TNAMB00483530000020685 | E5: 2013 | F5: Contribution | G5: 41571 | H5: Cont. For Due-Month 102013 | I5: 4321 | J5: 4321 | K5: 519 | L5: 159 | M5: 360
A6: Kurinji Malar Paranthaman | B6: 1.00199E+11 | C6: NTT DATA INFORMATION PROCESSING SERVICES PVT LTD | D6: TNAMB00483530000020685 | E6: 2013 | F6: Contribution | G6: 41613 | H6: Cont. For Due-Month 112013 | I6: 4630 | J6: 4630 | K6: 556 | L6: 170 | M6: 386
A7: Kurinji Malar Paranthaman | B7: 1.00199E+11 | C7: NTT DATA INFORMATION PROCESSING SERVICES PVT LTD | D7: TNAMB00483530000020685 | E7: 2013 | F7: Contribution | G7: 41634 | H7: Cont. For Due-Month 122013 | I7: 4630 | J7: 4630 | K7: 556 | L7: 170 | M7: 386
A8: Kurinji Malar Paranthaman | B8: 1.00199E+11 | C8: NTT DATA INFORMATION PROCESSING SERVICES PVT LTD | D8: TNAMB00483530000020685 | E8: 2013 | F8: Contribution | G8: 41662 | H8: Cont. For Due-Month 012014 | I8: 4630 | J8: 4630 | K8: 556 | L8: 170 | M8: 386
A9: Kurinji Malar Paranthaman | B9: 1.00199E+11 | C9: NTT DATA INFORMATION PROCESSING SERVICES PVT LTD | D9: TNAMB00483530000020685 | E9: 2013 | F9: Contribution | G9: 41705 | H9: Cont. For Due-Month 022014 | I9: 5324 | J9: 5324 | K9: 639 | L9: 196 | M9: 443
A10: Kurinji Malar Paranthaman | B10: 1.00199E+11 | C10: NTT DATA INFORMATION PROCESSING SERVICES PVT LTD | D10: TNAMB00483530000020685 | E10: 2013 | F10: Contribution | G10: 41723 | H10: Cont. For Due-Month 032014 | I10: 5324 | J10: 5324 | K10: 639 | L10: 196 | M10: 443
A11: Kurinji Malar Paranthaman | B11: 1.00199E+11 | C11: NTT DATA INFORMATION PROCESSING SERVICES PVT LTD | D11: TNAMB00483530000020685 | E11: 2013 | F11: Interest | G11: 41729 | H11: Interest Updated | K11: 134 | L11: 41 | M11: 0
A12: Kurinji Malar Paranthaman | B12: 1.00199E+11 | C12: NTT DATA INFORMATION PROCESSING SERVICES PVT LTD | D12: TNAMB00483530000020685 | E12: 2013 | F12: Closing Balance | G12: 41729 | H12: Closing Balance | K12: 5081 | L12: 1555 | M12: 3433
A13: Kurinji Malar Paranthaman | B13: 1.00199E+11 | C13: NTT DATA INFORMATION PROCESSING SERVICES PVT LTD | D13: TNAMB00483530000020685 | E13: 2014 | F13: Contribution | G13: 41758 | H13: Cont. For Due-Month 042014 | I13: 5324 | J13: 5324 | K13: 639 | L13: 196 | M13: 443
A14: Kurinji Malar Paranthaman | B14: 1.00199E+11 | C14: NTT DATA INFORMATION PROCESSING SERVICES PVT LTD | D14: TNAMB00483530000020685 | E14: 2014 | F14: Contribution | G14: 41779 | H14: Cont. For Due-Month 052014 | I14: 5324 | J14: 5324 | K14: 639 | L14: 196 | M14: 443
A15: Kurinji Malar Paranthaman | B15: 1.00199E+11 | C15: NTT DATA INFORMATION PROCESSING SERVICES PVT LTD | D15: TNAMB00483530000020685 | E15: 2014 | F15: Contribution | G15: 41809 | H15: Cont. For Due-Month 062014 | I15: 5324 | J15: 5324 | K15: 639 | L15: 196 | M15: 443
A16: Kurinji Malar Paranthaman | B16: 1.00199E+11 | C16: NTT DATA INFORMATION PROCESSING SERVICES PVT LTD | D16: TNAMB00483530000020685 | E16: 2014 | F16: Contribution | G16: 41850 | H16: Cont. For Due-Month 072014 | I16: 5324 | J16: 5324 | K16: 639 | L16: 196 | M16: 443
A17: Kurinji Malar Paranthaman | B17: 1.00199E+11 | C17: NTT DATA INFORMATION PROCESSING SERVICES PVT LTD | D17: TNAMB00483530000020685 | E17: 2014 | F17: Contribution | G17: 41876 | H17: Cont. For Due-Month 082014 | I17: 355 | J17: 355 | K17: 43 | L17: 13 | M17: 30
A18: Kurinji Malar Paranthaman | B18: 1.00564E+11 | C18: AGS HEALTH PVT LTD | D18: TNMAS00838510000003341 | E18: 2014 | F18: Contribution | G18: 41887 | H18: Cont. For Due-Month 082014 | I18: 2600 | J18: 2600 | K18: 312 | L18: 95 | M18: 217
A19: Kurinji Malar Paranthaman | B19: 1.00199E+11 | C19: NTT DATA INFORMATION PROCESSING SERVICES PVT LTD | D19: TNAMB00483530000020685 | E19: 2014 | F19: Contribution | G19: 41900 | H19: Cont. For Due-Month 092014 | I19: 0 | J19: 0 | K19: 0 | L19: 0 | M19: 0
A20: Kurinji Malar Paranthaman | B20: 1.00564E+11 | C20: AGS HEALTH PVT LTD | D20: TNMAS00838510000003341 | E20: 2014 | F20: Contribution | G20: 41920 | H20: Cont. For Due-Month 092014 | I20: 6283 | J20: 6283 | K20: 754 | L20: 231 | M20: 523
A21: Kurinji Malar Paranthaman | B21: 1.00564E+11 | C21: AGS HEALTH PVT LTD | D21: TNMAS00838510000003341 | E21: 2014 | F21: Contribution | G21: 42080 | H21: Cont. For Due-Month 032015 | I21: 6500 | J21: 6500 | K21: 780 | L21: 239 | M21: 541
A22: Kurinji Malar Paranthaman | B22: 1.00564E+11 | C22: AGS HEALTH PVT LTD | D22: TNMAS00838510000003341 | E22: 2014 | F22: Contribution | G22: 42088 | H22: Cont. For Due-Month 102014 | I22: 6500 | J22: 6500 | K22: 780 | L22: 239 | M22: 541
A23: Kurinji Malar Paranthaman | B23: 1.00564E+11 | C23: AGS HEALTH PVT LTD | D23: TNMAS00838510000003341 | E23: 2014 | F23: Contribution | G23: 42089 | H23: Cont. For Due-Month 122014 | I23: 6500 | J23: 6500 | K23: 780 | L23: 239 | M23: 541
A24: Kurinji Malar Paranthaman | B24: 1.00564E+11 | C24: AGS HEALTH PVT LTD | D24: TNMAS00838510000003341 | E24: 2014 | F24: Contribution | G24: 42089 | H24: Cont. For Due-Month 012015 | I24: 6500 | J24: 6500 | K24: 780 | L24: 239 | M24: 541
A25: Kurinji Malar Paranthaman | B25: 1.00564E+11 | C25: AGS HEALTH PVT LTD | D25: TNMAS00838510000003341 | E25: 2014 | F25: Contribution | G25: 42089 | H25: Cont. For Due-Month 022015 | I25: 6500 | J25: 6500 | K25: 780 | L25: 239 | M25: 541
A26: Kurinji Malar Paranthaman | B26: 1.00199E+11 | C26: NTT DATA INFORMATION PROCESSING SERVICES PVT LTD | D26: TNAMB00483530000020685 | E26: 2014 | F26: Interest | G26: 42094 | H26: Interest Updated | K26: 624 | L26: 191 | M26: 0
A27: Kurinji Malar Paranthaman | B27: 1.00199E+11 | C27: NTT DATA INFORMATION PROCESSING SERVICES PVT LTD | D27: TNAMB00483530000020685 | E27: 2014 | F27: Closing Balance | G27: 42094 | H27: Closing Balance | K27: 8304 | L27: 2543 | M27: 5235
A28: Kurinji Malar Paranthaman | B28: 1.00564E+11 | C28: AGS HEALTH PVT LTD | D28: TNMAS00838510000003341 | E28: 2014 | F28: Contribution | G28: 42094 | H28: Cont. For Due-Month 112014 | I28: 6067 | J28: 6067 | K28: 728 | L28: 223 | M28: 505
A29: Kurinji Malar Paranthaman | B29: 1.00564E+11 | C29: AGS HEALTH PVT LTD | D29: TNMAS00838510000003341 | E29: 2014 | F29: Interest | G29: 42094 | H29: Interest Updated | K29: 133 | L29: 41 | M29: 0
A30: Kurinji Malar Paranthaman | B30: 1.00564E+11 | C30: AGS HEALTH PVT LTD | D30: TNMAS00838510000003341 | E30: 2014 | F30: Closing Balance | G30: 42094 | H30: Closing Balance | K30: 5827 | L30: 1785 | M30: 3950
A31: Kurinji Malar Paranthaman | B31: 1.00564E+11 | C31: AGS HEALTH PVT LTD | D31: TNMAS00838510000003341 | E31: 2015 | F31: Contribution | G31: 42145 | H31: Cont. For Due-Month 042015 | I31: 6500 | J31: 6500 | K31: 780 | L31: 239 | M31: 541
A32: Kurinji Malar Paranthaman | B32: 1.00564E+11 | C32: AGS HEALTH PVT LTD | D32: TNMAS00838510000003341 | E32: 2015 | F32: Contribution | G32: 42157 | H32: Cont. For Due-Month 052015 | I32: 6500 | J32: 6500 | K32: 780 | L32: 239 | M32: 541
A33: Kurinji Malar Paranthaman | B33: 1.00564E+11 | C33: AGS HEALTH PVT LTD | D33: TNMAS00838510000003341 | E33: 2015 | F33: Contribution | G33: 42185 | H33: Cont. For Due-Month 062015 | I33: 0 | J33: 0 | K33: 1 | L33: 1 | M33: 1
A34: Kurinji Malar Paranthaman | B34: 1.00649E+11 | C34: MEDUSIND SOLUTIONS | D34: TNMAS00497090000002652 | E34: 2015 | F34: Contribution | G34: 42221 | H34: Cont. For Due-Month 062015 | I34: 4925 | J34: 4925 | K34: 591 | L34: 181 | M34: 410
